<?xml version="1.0"?>

<robot xmlns:xacro="http://www.ros.org/wiki/xacro">

  <xacro:include filename="$(find suction_urdf)/urdf/suction.transmission.xacro" />
  <xacro:include filename="$(find suction_urdf)/urdf/suction.gazebo.xacro" />

  <xacro:macro name="suction" params="side parent *origin">  
    <link
      name="${side}_tool_link">
      <inertial>
        <origin
          xyz="-0.003041 0.0027723 0.043545"
          rpy="0 0 0" />
        <mass
          value="0.11123" />
        <inertia
          ixx="8.4875E-05"
          ixy="4.1003E-07"
          ixz="4.0241E-06"
          iyy="0.00010438"
          iyz="6.5325E-07"
          izz="4.7593E-05" />
      </inertial>
      <visual>
        <origin
          xyz="0 0 0"
          rpy="0 0 0" />
        <geometry>
          <mesh
            filename="package://suction_urdf/meshes/tool_link.STL" />
        </geometry>
        <material
          name="">
          <color
            rgba="1 1 1 1" />
        </material>
      </visual>
      <collision>
        <origin
          xyz="0 0 0"
          rpy="0 0 0" />
        <geometry>
          <mesh
            filename="package://suction_urdf/meshes/tool_link.STL" />
        </geometry>
      </collision>
    </link>
    <link
      name="${side}_tool_end_Link">
      <inertial>
        <origin
          xyz="9.909E-05 0.0039906 0.025651"
          rpy="0 0 0" />
        <mass
          value="0.033438" />
        <inertia
          ixx="2.0813E-05"
          ixy="1.7379E-08"
          ixz="9.2823E-08"
          iyy="1.8619E-05"
          iyz="4.6462E-06"
          izz="5.6779E-06" />
      </inertial>
      <visual>
        <origin
          xyz="0 0 0"
          rpy="0 0 0" />
        <geometry>
          <mesh
            filename="package://suction_urdf/meshes/tool_end_Link.STL" />
        </geometry>
        <material
          name="">
          <color
            rgba="0.79216 0.81961 0.93333 1" />
        </material>
      </visual>
      <collision>
        <origin
          xyz="0 0 0"
          rpy="0 0 0" />
        <geometry>
          <mesh
            filename="package://suction_urdf/meshes/tool_end_Link.STL" />
        </geometry>
      </collision>
    </link>
    <joint
      name="${side}_tool_joint"
      type="revolute">
      <origin
        xyz="0 0.002 0.1045"
        rpy="-1.7985E-15 -2.9973E-16 1.1669E-16" />
      <parent
        link="${side}_tool_link" />
      <child
        link="${side}_tool_end_Link" />
      <axis
        xyz="0 1 0" />
      <limit
        lower="-3.14"
	      upper="3.14"
        effort="5"
        velocity="5" />
    </joint>

    <xacro:suction_transmission side="${side}" />
    <xacro:suction_gazebo side="${side}" />
  </xacro:macro>
</robot>
